Workbook

Sheet Plantilla Inventario
A1: Código de Barras | B1: Producto / Nombre | C1: Marca | D1: Cantidad (Stock) | E1: Precio Neto | F1: Impuestos | G1: Precio Venta | H1: Categoría
A2: 7591260070856 | B2: ACEITE 5X1 SQ (GOTERO) | C2: SQ | D2: {=XLOOKUP(B2, Inventario_viejo!A:A, Inventario_viejo!B:B, "No encontrado", 0)} -> 1 | E2: 2.15 | F2: 0.4 | G2: 6 | H2: Multiusos / Lubricantes
A3: 7591260070795 | B3: ACEITE 5X1 SQ (SPRAY) | C3: SQ | D3: {=XLOOKUP(B3, Inventario_viejo!A:A, Inventario_viejo!B:B, "No encontrado", 0)} -> 2 | E3: 3.8 | F3: 0.4 | G3: 9 | H3: Multiusos / Lubricantes
A4: 7598188000231 | B4: ACEITE POWERSTEARING FLUIDS CHRONUS (473ml) | C4: CHRONUS | D4: 9 | E4: 4.8 | F4: 0.4 | G4: 8 | H4: =IFERROR(__xludf.DUMMYFUNCTION("AI(""Introduce un valor adecuado para esta celda según el contexto de la tabla"")"),"Aceite / Transmisión") -> Aceite / Transmisión
A5: 071153002043 | B5: ACEITE POWERSTEARING FLUIDS STP (354ml) | C5: STP | D5: {=XLOOKUP(B5, Inventario_viejo!A:A, Inventario_viejo!B:B, "No encontrado", 0)} -> 8 | E5: 7.3 | F5: 0.4 | G5: 9 | H5: =IFERROR(__xludf.DUMMYFUNCTION("AI(""Introduce un valor adecuado para esta celda según el contexto de la tabla"")"),"Aceite / Transmisión") -> Aceite / Transmisión
A6: N/A | B6: ACEITE POWERSTEARING FLUIDS STP (946ml) | C6: STP | D6: 0 | E6: 7.3 | F6: 0.4 | G6: 15 | H6: =IFERROR(__xludf.DUMMYFUNCTION("AI(""Introduce un valor adecuado para esta celda según el contexto de la tabla"")"),"Aceite / Transmisión") -> Aceite / Transmisión | L6: =IFERROR(__xludf.DUMMYFUNCTION("IMPORTRANGE(""https://docs.google.com/spreadsheets/d/1wFcznqessZzenIhUngfAoNWXwGMCTqiG/edit?gid=178502302#gid=178502302"", ""Hoja1!A1"")"),"#REF!") -> #REF!
A7: 0740111725040 | B7: ACEITE ROYAL 80W-90 TRASMISION | C7: ROYAL | D7: 4 | E7: 7.3 | F7: 0.4 | G7: 12 | H7: =IFERROR(__xludf.DUMMYFUNCTION("AI(""Introduce un valor adecuado para esta celda según el contexto de la tabla"")"),"Aceite / Transmisión") -> Aceite / Transmisión
A8: 7598870000907 | B8: ACEITE GLOBAL OIL 80W-90 TRASMISION | C8: GLOBAL OIL | D8: 12 | E8: 7.3 | F8: 0.4 | G8: 12 | H8: =IFERROR(__xludf.DUMMYFUNCTION("AI(""Introduce un valor adecuado para esta celda según el contexto de la tabla"")"),"Aceite / Transmisión") -> Aceite / Transmisión
A9: 75996559000118 | B9: ACEITE VOLTEX 85W-140 MINERAL TRASMISION | C9: VOLTEX | D9: 6 | G9: 12 | H9: =IFERROR(__xludf.DUMMYFUNCTION("AI(""Introduce un valor adecuado para esta celda según el contexto de la tabla"")"),"Aceite / Transmisión") -> Aceite / Transmisión
A10: N/A | B10: ACEITE DAUER M5 ATF SYNTHETIC (946ml) | C10: DAUER | D10: 0 | E10: 7.3 | F10: 0.4 | G10: 0 | H10: =IFERROR(__xludf.DUMMYFUNCTION("AI(""Introduce un valor adecuado para esta celda según el contexto de la tabla"")"),"Aceite / Transmisión") -> Aceite / Transmisión
A11: 816645011727 | B11: ACEITE DAUER CVT ATF SYNTHETIC (946ml) | C11: DAUER | D11: {=XLOOKUP(B11, Inventario_viejo!A:A, Inventario_viejo!B:B, "No encontrado", 0)} -> 6 | E11: 7.3 | F11: 0.4 | G11: 20 | H11: =IFERROR(__xludf.DUMMYFUNCTION("AI(""Introduce un valor adecuado para esta celda según el contexto de la tabla"")"),"Aceite / Transmisión") -> Aceite / Transmisión
A12: 7596433041671 | B12: ACEITE KYOTO CVT FE (946ml) | C12: KYOTO | D12: {=XLOOKUP(B12, Inventario_viejo!A:A, Inventario_viejo!B:B, "No encontrado", 0)} -> 6 | E12: 7.3 | F12: 0.4 | G12: 17 | H12: =IFERROR(__xludf.DUMMYFUNCTION("AI(""Introduce un valor adecuado para esta celda según el contexto de la tabla"")"),"Aceite / Transmisión") -> Aceite / Transmisión
A13: 7898319232242 | B13: ACEITE BLUE1 ATF DX IV (1L) | C13: BLUE1 | D13: 9 | E13: 7.3 | F13: 0.4 | G13: 17 | H13: =IFERROR(__xludf.DUMMYFUNCTION("AI(""Introduce un valor adecuado para esta celda según el contexto de la tabla"")"),"Aceite / Transmisión") -> Aceite / Transmisión
A14: N/A | B14: ACEITE PROFORCE DEXRON III (946ml) | C14: PROFORCE | D14: 0 | F14: 0.4 | G14: 10 | H14: =IFERROR(__xludf.DUMMYFUNCTION("AI(""Introduce un valor adecuado para esta celda según el contexto de la tabla"")"),"Aceite / Transmisión") -> Aceite / Transmisión
A15: N/A | B15: ACEITE XPESO DEXRON III (946ml) | C15: XPESO | D15: 12 | F15: 0.4 | G15: 10 | H15: =IFERROR(__xludf.DUMMYFUNCTION("AI(""Introduce un valor adecuado para esta celda según el contexto de la tabla"")"),"Aceite / Transmisión") -> Aceite / Transmisión
A16: 840984173099 | B16: ACEITE MOPAR ATF+4 SYNTHETIC (946ml) | C16: MOPAR | D16: 2 | G16: 18 | H16: =IFERROR(__xludf.DUMMYFUNCTION("AI(""Introduce un valor adecuado para esta celda según el contexto de la tabla"")"),"Aceite / Transmisión") -> Aceite / Transmisión
A17: 7599659000071 | B17: ACEITE VOLTEX DEXRON III (946ml) | C17: VOLTEX | D17: 5 | F17: 0.4 | G17: 11 | H17: Aceite / Transmisión
A18: 7898319231603 | B18: ACEITE SUPERIOR DEXRON III (1L) | C18: SUPERIOR | D18: 8 | F18: 0.4 | G18: 11 | H18: Aceite / Transmisión
A19: 7501247408121 | B19: ACEITE GONHER ATF DEXRON III (946ml) | C19: GONHER | D19: 15 | F19: 0.4 | G19: 14 | H19: Aceite / Transmisión
A20: 7598188000149 | B20: ACEITE CHRONUS DEXRON III (946ml) | C20: =MID(B20,FIND(" ",B20) + 1,FIND(CHAR(160),SUBSTITUTE(B20," ",CHAR(160),2)) - 1 - (FIND(" ",B20))) -> CHRONUS | D20: 5 | F20: 0.4 | G20: 15 | H20: Aceite / Transmisión
A21: 7898319231306 | B21: ACEITE BLUE1 DEXRON III (1L) | C21: =MID(B21,FIND(" ",B21) + 1,FIND(CHAR(160),SUBSTITUTE(B21," ",CHAR(160),2)) - 1 - (FIND(" ",B21))) -> BLUE1 | D21: 9 | F21: 0.4 | G21: 15 | H21: Aceite / Transmisión
A22: 7593891000677 | B22: ACEITE OILVEN ATF DEXRON III (946ml) | C22: OILVEN | D22: 3 | G22: 11 | H22: Aceite / Transmisión
A23: 7704790200383 | B23: ACEITE MOBIL ATF DEXRON III (946ml) | C23: MOBIL | D23: 6 | G23: 16 | H23: Aceite / Transmisión
A24: 729208125895 | B24: ACEITE INGRALUB ATF DEXRON III (946ml) | C24: INGRALUB | D24: 2 | G24: 11 | H24: =IFERROR(__xludf.DUMMYFUNCTION("AI(""Introduce un valor adecuado para esta celda según el contexto de la tabla"")"),"Aceite / Transmisión") -> Aceite / Transmisión
A25: 7591871007968 | B25: ACEITE ULTRALUB ATF DEXRON III (946ml) | C25: ULTRALUB | D25: 8 | G25: 16 | H25: Aceite / Transmisión
A27: ACEITES MOTOR REVISAR
A28: N/A | B28: ACEITE FC 20W-50 MINERAL (MOTO) | C28: =MID(B28,FIND(" ",B28) + 1,FIND(CHAR(160),SUBSTITUTE(B28," ",CHAR(160),2)) - 1 - (FIND(" ",B28))) -> FC | D28: 0 | F28: 0.4 | G28: 10 | H28: Aceite / Moto
A29: 7593597002586 | B29: ACEITE OILSTONE 20W-50 MINERAL (MOTO) | C29: =MID(B29,FIND(" ",B29) + 1,FIND(CHAR(160),SUBSTITUTE(B29," ",CHAR(160),2)) - 1 - (FIND(" ",B29))) -> OILSTONE | D29: 8 | F29: 0.4 | G29: 12 | H29: Aceite / Moto
A30: 7593597002685 | B30: ACEITE SKY 20W-50 4T SEMISINTETICO (946ml) (MOTO) | C30: SKY | D30: 6 | F30: 0.4 | G30: 15 | H30: Aceite / Moto
A31: 7591871008088 | B31: ACEITE ULTRALUB 10W-40 4T SEMISINTETICO (1L) (MOTO) | C31: ULTRALUB | D31: 6 | F31: 0.4 | G31: 16 | H31: Aceite / Moto
A32: 7591871008057 | B32: ACEITE ULTRALUB 20W-50 4T MINERAL (1L) (MOTO) | C32: ULTRALUB | D32: 3 | F32: 0.4 | G32: 16 | H32: Aceite / Moto
A33: 75011390569397 | B33: ACEITE ROSHFRANS 2T MINERAL (MOTO) | C33: =MID(B33,FIND(" ",B33) + 1,FIND(CHAR(160),SUBSTITUTE(B33," ",CHAR(160),2)) - 1 - (FIND(" ",B33))) -> ROSHFRANS | D33: 2 | F33: 0.4 | G33: 14 | H33: Aceite / Moto
A34: N/A | B34: ACEITE ROSHFRANS 10W-40 SEMISINTETICO (MOTO) | C34: =MID(B34,FIND(" ",B34) + 1,FIND(CHAR(160),SUBSTITUTE(B34," ",CHAR(160),2)) - 1 - (FIND(" ",B34))) -> ROSHFRANS | D34: 0 | F34: 0.4 | G34: 16 | H34: Aceite / Moto
A35: 7501390569410 | B35: ACEITE ROSHFRANS 10W-50 4T 100% SINTETICO (946ml) (MOTO) | C35: =MID(B35,FIND(" ",B35) + 1,FIND(CHAR(160),SUBSTITUTE(B35," ",CHAR(160),2)) - 1 - (FIND(" ",B35))) -> ROSHFRANS | D35: {=XLOOKUP(B35, Inventario_viejo!A:A, Inventario_viejo!B:B, "No encontrado",1,1)} -> 26 | F35: 0.4 | G35: 18 | H35: Aceite / Moto
A36: N/A | B36: ACEITE MOTUL 3000 20W/50 MINERAL (MOTO) | C36: =MID(B36,FIND(" ",B36) + 1,FIND(CHAR(160),SUBSTITUTE(B36," ",CHAR(160),2)) - 1 - (FIND(" ",B36))) -> MOTUL | D36: 0 | F36: 0.4 | G36: 18 | H36: Aceite / Moto
A37: 3374650247205 | B37: ACEITE MOTUL 5100 15W/50 SIMISINTETICO (1L) (MOTO) | C37: =MID(B37,FIND(" ",B37) + 1,FIND(CHAR(160),SUBSTITUTE(B37," ",CHAR(160),2)) - 1 - (FIND(" ",B37))) -> MOTUL | D37: 2 | G37: 23 | H37: Aceite / Moto
A38: 3700142305120 | B38: ACEITE IPONE 15W/50 SEMISINTETICO (1L )(MOTO) | C38: =MID(B38,FIND(" ",B38) + 1,FIND(CHAR(160),SUBSTITUTE(B38," ",CHAR(160),2)) - 1 - (FIND(" ",B38))) -> IPONE | D38: 5 | G38: 20 | H38: Aceite / Moto
A39: 3700142304994 | B39: ACEITE IPONE 20W/50 SEMISINTETICO (1L) (MOTO) | C39: =MID(B39,FIND(" ",B39) + 1,FIND(CHAR(160),SUBSTITUTE(B39," ",CHAR(160),2)) - 1 - (FIND(" ",B39))) -> IPONE | D39: 5 | F39: 0.4 | G39: 20 | H39: Aceite / Moto
A40: 2140009127 | B40: ACEITE SHELL 20W/50 PREMIUM MINERAL 4T (1L) (MOTO) | C40: SHELL | D40: 4 | G40: 18 | H40: Aceite / Moto
A41: 7898319235571 | B41: ACEITE BLUE1 15W/40 MINERAL | C41: =MID(B42,FIND(" ",B42) + 1,FIND(CHAR(160),SUBSTITUTE(B42," ",CHAR(160),2)) - 1 - (FIND(" ",B42))) -> BLUE1 | D41: {=XLOOKUP(B41, Inventario_viejo!A:A, Inventario_viejo!B:B, "No encontrado",1,1)} -> 12 | F41: 0.3 | G41: 15 | H41: Aceite / Motor
...

Sheet Inventario_viejo
A1: ESTANTE LARSSON
A2: PRODUCTOS | B2: CANTIDAD | C2: P.UNIT | D2: VENDIDOS | E2: TOTAL | F2: IMPUESTOS | G2: SUBTOTAL | H2: TOTAL DÓLAR | I2: TOTAL
A3: CEPILLO LARSSON REAR TECH 8" | B3: 0 | C3: 2 | D3: 0 | E3: =+B3-D3 -> 0 | F3: 0.4 | G3: =C3+(C3*F3) -> 2.8 | H3: 10 | I3: =+E3*H3 -> 0
A4: CEPILLO LARSSON REAR TECH 9" | B4: 0 | C4: 2 | D4: 0 | E4: =+B4-D4 -> 0 | F4: 0.4 | G4: =C4+(C4*F4) -> 2.8 | H4: 10 | I4: =+E4*H4 -> 0
A5: CEPILLO LARSSON REAR TECH 10" | B5: 4 | C5: 2.27 | D5: 0 | E5: =+B5-D5 -> 4 | F5: 0.4 | G5: =C5+(C5*F5) -> 3.178 | H5: 10 | I5: =+E5*H5 -> 40
A6: CEPILLO LARSSON REAR TECH 11" | B6: 2 | C6: 2.31 | D6: 0 | E6: =+B6-D6 -> 2 | F6: 0.4 | G6: =C6+(C6*F6) -> 3.234 | H6: 10 | I6: =+E6*H6 -> 20
A7: CEPILLO LARSSON REAR TECH 12" | B7: 3 | C7: 2.31 | D7: 0 | E7: =+B7-D7 -> 3 | F7: 0.4 | G7: =C7+(C7*F7) -> 3.234 | H7: 10 | I7: =+E7*H7 -> 30
A8: CEPILLO LARSSON REAR TECH 13" | B8: 2 | C8: 2.47 | D8: 0 | E8: =+B8-D8 -> 2 | F8: 0.4 | G8: =C8+(C8*F8) -> 3.458 | H8: 10 | I8: =+E8*H8 -> 20
A9: CEPILLO LARSSON REAR TECH 14" | B9: 4 | C9: 2 | D9: 0 | E9: =+B9-D9 -> 4 | F9: 0.4 | G9: =C9+(C9*F9) -> 2.8 | H9: 10 | I9: =+E9*H9 -> 40
A10: CEPILLO LARSSON FLEX TECH 12" | B10: 6 | C10: 2.9 | D10: 0 | E10: =+B10-D10 -> 6 | F10: 0.4 | G10: =C10+(C10*F10) -> 4.06 | H10: 10 | I10: =+E10*H10 -> 60
A11: CEPILLO LARSSON FLEX TECH 13" | B11: 7 | C11: 2.9 | D11: 0 | E11: =+B11-D11 -> 7 | F11: 0.4 | G11: =C11+(C11*F11) -> 4.06 | H11: 10 | I11: =+E11*H11 -> 70
A12: CEPILLO LARSSON FLEX TECH 14" | B12: 7 | C12: 2.99 | D12: 0 | E12: =+B12-D12 -> 7 | F12: 0.4 | G12: =C12+(C12*F12) -> 4.186 | H12: 10 | I12: =+E12*H12 -> 70
A13: CEPILLO LARSSON FLEX TECH 15" | B13: 5 | C13: 3.04 | D13: 0 | E13: =+B13-D13 -> 5 | F13: 0.4 | G13: =C13+(C13*F13) -> 4.256 | H13: 10 | I13: =+E13*H13 -> 50
A14: CEPILLO LARSSON FLEX TECH 16" | B14: 5 | C14: 3.11 | D14: 0 | E14: =+B14-D14 -> 5 | F14: 0.4 | G14: =C14+(C14*F14) -> 4.354 | H14: 10 | I14: =+E14*H14 -> 50
... A33: CEPILLO LARSSON ROBOT TECH 26" | B33: 1 | C33: 4.31 | D33: 0 | E33: =+B33-D33 -> 1 | F33: 0.4 | G33: =C33+(C33*F33) -> 6.034 | H33: 11 | I33: =+E33*H33 -> 11
B34: =SUM(B3:B33) -> 115 | H34: TOTAL | I34: =SUM(I3:I33) -> 1205
A36: CARRITO DE 4 TRAMOS
A37: PRODUCTOS | B37: CANTIDAD | C37: P.UNIT | D37: VENDIDOS | E37: TOTAL | F37: IMPUESTOS | G37: SUBTOTAL | H37: TOTAL DÓLAR | I37: TOTAL
A38: LIMPIA CAUCHOS SQ (440cm) | B38: 4 | C38: 8.28 | D38: 0 | E38: =+B38-D38 -> 4 | F38: 0.4 | G38: =C38+(C38*F38) -> 11.592 | H38: 12 | I38: =+E38*H38 -> 48
A39: LIMPIA MOTOR SQ (354cm) | B39: 7 | C39: 6.33 | D39: 0 | E39: =+B39-D39 -> 7 | F39: 0.4 | G39: =C39+(C39*F39) -> 8.862 | H39: 10 | I39: =+E39*H39 -> 70
A40: LIMPIA CARBURADOR SQ (354cm) | B40: 2 | C40: 6.64 | D40: 0 | E40: =+B40-D40 -> 2 | F40: 0.4 | G40: =C40+(C40*F40) -> 9.296 | H40: 10 | I40: =+E40*H40 -> 20
A41: LIMPIA TAPICERIA VELOUR (354cm) | B41: 2 | C41: 3.15 | D41: 0 | E41: =+B41-D41 -> 2 | F41: 0.4 | G41: =C41+(C41*F41) -> 4.41 | H41: 13 | I41: =+E41*H41 -> 26
A42: LIMPIADOR DE CUERO SQ (360cm) | B42: 1 | C42: 3.15 | D42: 0 | E42: =+B42-D42 -> 1 | F42: 0.4 | G42: =C42+(C42*F42) -> 4.41 | H42: 13 | I42: =+E42*H42 -> 13
A43: SILICON ABRILLANTADOR MORADO SQ (SPRAY) (354cm) | B43: 2 | C43: 4.05 | D43: 0 | E43: =+B43-D43 -> 2 | F43: 0.4 | G43: =C43+(C43*F43) -> 5.67 | H43: 9 | I43: =+E43*H43 -> 18
A44: SILICON ABRILLANTADOR VERDE SQ (SPRAY) (354cm) | B44: 1 | C44: 4.05 | D44: 0 | E44: =+B44-D44 -> 1 | F44: 0.4 | G44: =C44+(C44*F44) -> 5.67 | H44: 9 | I44: =+E44*H44 -> 9
A45: SILICON ABRILLANTADOR ROJO SQ (SPRAY) (354cm) | B45: 1 | C45: 4.05 | D45: 0 | E45: =+B45-D45 -> 1 | F45: 0.4 | G45: =C45+(C45*F45) -> 5.67 | H45: 9 | I45: =+E45*H45 -> 9
A46: SILIFLON SQ (MOTOS) | B46: 4 | C46: 5.95 | D46: 0 | E46: =+B46-D46 -> 4 | F46: 0.4 | G46: =C46+(C46*F46) -> 8.33 | H46: 9 | I46: =+E46*H46 -> 36
A47: ACEITE 5X1 SQ (GOTERO) | B47: 1 | C47: 2.15 | D47: 0 | E47: =+B47-D47 -> 1 | F47: 0.4 | G47: =C47+(C47*F47) -> 3.01 | H47: 6 | I47: =+E47*H47 -> 6
A48: ACEITE 5X1 SQ (SPRAY) | B48: 2 | C48: 3.8 | D48: 0 | E48: =+B48-D48 -> 2 | F48: 0.4 | G48: =C48+(C48*F48) -> 5.32 | H48: 9 | I48: =+E48*H48 -> 18
A49: FORMULA MECANICA SQ (354cm) | B49: 4 | C49: 3.45 | D49: 0 | E49: =+B49-D49 -> 4 | F49: 0.4 | G49: =C49+(C49*F49) -> 4.83 | H49: 10 | I49: =+E49*H49 -> 40
... A59: WD-40 AEROSOL 8 ONZAS | B59: 1 | C59: 5.25 | D59: 0 | E59: =+B59-D59 -> 1 | F59: 0.4 | G59: =C59+(C59*F59) -> 7.35 | H59: 15 | I59: =+E59*H59 -> 15
A60: TRATAMIENTO CAJA DE CAMBIOS TRATAUTO | B60: 0 | C60: 5.25 | F60: 0.3 | G60: =C60+(C60*F60) -> 6.825 | H60: 25 | I60: =+E60*H60 -> 0
A61: TRATAMIENTO ANTIFRICCION POWER METAL TRATAUTO (MOTOR) | B61: 2 | C61: 5.25 | D61: 0 | E61: =+B61-D61 -> 2 | F61: 0.3 | G61: =C61+(C61*F61) -> 6.825 | H61: 25 | I61: =+E61*H61 -> 50
A62: SUPER MULTIUSO TODO EN 1 TRATAUTO (600 ml) | B62: 3 | C62: 5.25 | D62: 0 | E62: =+B62-D62 -> 3 | F62: 0.3 | G62: =C62+(C62*F62) -> 6.825 | H62: 20 | I62: =+E62*H62 -> 60
A63: LIMPIADOR DE FRENOS TRATAUTO (550 ml) | B63: 3 | C63: 5.25 | D63: 0 | E63: =+B63-D63 -> 3 | F63: 0.3 | G63: =C63+(C63*F63) -> 6.825 | H63: 14 | I63: =+E63*H63 -> 42
A64: LIMPIADOR DE TAPICERIA TRATAUTO (400 ml) | B64: 1 | C64: 5.25 | D64: 0 | E64: =+B64-D64 -> 1 | F64: 0.3 | G64: =C64+(C64*F64) -> 6.825 | H64: 17 | I64: =+E64*H64 -> 17
A65: NEUTRALIZADOR DE OLORES TRATAUTO (300 ml) | B65: 1 | C65: 5.25 | D65: 0 | E65: =+B65-D65 -> 1 | F65: 0.4 | G65: =C65+(C65*F65) -> 7.35 | H65: 15 | I65: =+E65*H65 -> 15
A66: LIMPIA INYECTORES GASOLINA TRATAUTO (300 ml) | B66: 1 | C66: 5.25 | D66: 0 | E66: =+B66-D66 -> 1 | F66: 0.4 | G66: =C66+(C66*F66) -> 7.35 | H66: 18 | I66: =+E66*H66 -> 18
A67: POWER OCTANE BOOSTER TRATAUTO (150 ml) | B67: 1 | C67: 5.25 | D67: 0 | E67: =+B67-D67 -> 1 | F67: 0.4 | G67: =C67+(C67*F67) -> 7.35 | H67: 11 | I67: =+E67*H67 -> 11
A68: PROTECTOR ABRILLANTADOR SPRAY ARMORALL (295ml) | B68: 2 | C68: 5.25 | D68: 0 | E68: =+B68-D68 -> 2 | F68: 0.4 | G68: =C68+(C68*F68) -> 7.35 | H68: 12 | I68: =+E68*H68 -> 24
...
